Workbook

Sheet Original Data
A1: OrderID | B1: Date | C1: CustomerID | D1: Product | E1: Quantity | F1: UnitPrice | G1: ShippingAddress | H1: PaymentMethod | I1: OrderStatus | J1: TrackingNumber | K1: ItemsInCart | L1: CouponCode | M1: ReferralSource | N1: TotalPrice
A2: ORD200000 | B2: 44930 | C2: C72649 | D2: Monitor | E2: 5 | F2: 570.62 | G2: 928 Main St | H2: Debit Card | I2: Shipped | J2: TRK37947903 | K2: 7 | L2: SAVE10 | M2: Instagram | N2: 2853.1
A3: ORD200001 | B3: 45527 | C3: C75739 | D3: Phone | E3: 2 | F3: 151.35 | G3: 823 Main St | H3: Online | I3: Shipped | J3: TRK91186779 | K3: 3 | L3: SAVE10 | M3: Referral | N3: 302.7
A4: ORD200002 | B4: 45349 | C4: C81728 | D4: Tablet | E4: 5 | F4: 550.68 | G4: 512 Main St | H4: Credit Card | I4: Cancelled | J4: TRK42903982 | K4: 8 | L4: FREESHIP | M4: Email | N4: 2753.4
A5: ORD200003 | B5: 45214 | C5: C33540 | D5: Chair | E5: 1 | F5: 273.19 | G5: 275 Main St | H5: Debit Card | I5: Returned | J5: TRK62788070 | K5: 5 | L5: SAVE10 | M5: Facebook | N5: 273.19
A6: ORD200004 | B6: 45785 | C6: C81840 | D6: Printer | E6: 4 | F6: 626.01 | G6: 668 Main St | H6: Online | I6: Delivered | J6: TRK29241424 | K6: 8 | L6: SAVE10 | M6: Email | N6: 2504.04
A7: ORD200005 | B7: 45222 | C7: C37249 | D7: Phone | E7: 2 | F7: 245.86 | G7: 934 Main St | H7: Credit Card | I7: Shipped | J7: TRK72976927 | K7: 4 | L7: SAVE10 | M7: Instagram | N7: 491.72
A8: ORD200006 | B8: 45825 | C8: C83492 | D8: Laptop | E8: 1 | F8: 664.42 | G8: 986 Main St | H8: Gift Card | I8: Returned | J8: TRK96417362 | K8: 6 | L8: SAVE10 | M8: Facebook | N8: 664.42
A9: ORD200007 | B9: 45058 | C9: C41460 | D9: Monitor | E9: 5 | F9: 149.55 | G9: 706 Main St | H9: Cash | I9: Shipped | J9: TRK78809193 | K9: 9 | L9: FREESHIP | M9: Facebook | N9: 747.75
A10: ORD200008 | B10: 45749 | C10: C26817 | D10: Phone | E10: 2 | F10: 134.28 | G10: 904 Main St | H10: Gift Card | I10: Cancelled | J10: TRK61042692 | K10: 2 | M10: Email | N10: 268.56
A11: ORD200009 | B11: 45251 | C11: C31946 | D11: Desk | E11: 4 | F11: 509.38 | G11: 102 Main St | H11: Credit Card | I11: Shipped | J11: TRK33478363 | K11: 6 | L11: SAVE10 | M11: Google | N11: 2037.52
A12: ORD200010 | B12: 45289 | C12: C43443 | D12: Tablet | E12: 5 | F12: 625.97 | G12: 333 Main St | H12: Credit Card | I12: Returned | J12: TRK98859248 | K12: 9 | L12: WINTER15 | M12: Instagram | N12: 3129.85
A13: ORD200011 | B13: 45339 | C13: C93861 | D13: Monitor | E13: 3 | F13: 49.14 | G13: 831 Main St | H13: Online | I13: Returned | J13: TRK48234646 | K13: 7 | L13: SAVE10 | M13: Email | N13: 147.42
A14: ORD200012 | B14: 45580 | C14: C38785 | D14: Monitor | E14: 2 | F14: 180.5 | G14: 179 Main St | H14: Debit Card | I14: Pending | J14: TRK20419991 | K14: 6 | L14: FREESHIP | M14: Referral | N14: 361
A15: ORD200013 | B15: 45168 | C15: C88348 | D15: Laptop | E15: 3 | F15: 201.49 | G15: 903 Main St | H15: Credit Card | I15: Returned | J15: TRK81913874 | K15: 4 | L15: FREESHIP | M15: Facebook | N15: 604.47
A16: ORD200014 | B16: 45012 | C16: C98474 | D16: Tablet | E16: 2 | F16: 393.33 | G16: 980 Main St | H16: Debit Card | I16: Pending | J16: TRK79186539 | K16: 3 | L16: SAVE10 | M16: Instagram | N16: 786.66
A17: ORD200015 | B17: 45124 | C17: C39416 | D17: Printer | E17: 1 | F17: 473.96 | G17: 942 Main St | H17: Cash | I17: Delivered | J17: TRK54930938 | K17: 3 | M17: Google | N17: 473.96
A18: ORD200016 | B18: 44950 | C18: C28976 | D18: Printer | E18: 2 | F18: 533.81 | G18: 914 Main St | H18: Credit Card | I18: Pending | J18: TRK13194259 | K18: 3 | L18: FREESHIP | M18: Email | N18: 1067.62
A19: ORD200017 | B19: 45353 | C19: C60672 | D19: Tablet | E19: 1 | F19: 423.4 | G19: 382 Main St | H19: Debit Card | I19: Shipped | J19: TRK11972116 | K19: 3 | M19: Referral | N19: 423.4
A20: ORD200018 | B20: 45742 | C20: C84329 | D20: Desk | E20: 1 | F20: 431.44 | G20: 891 Main St | H20: Gift Card | I20: Pending | J20: TRK65191045 | K20: 3 | L20: SAVE10 | M20: Facebook | N20: 431.44
A21: ORD200019 | B21: 44949 | C21: C14552 | D21: Monitor | E21: 5 | F21: 224 | G21: 273 Main St | H21: Cash | I21: Returned | J21: TRK59101365 | K21: 9 | L21: SAVE10 | M21: Google | N21: 1120
A22: ORD200020 | B22: 45054 | C22: C54829 | D22: Chair | E22: 5 | F22: 62.51 | G22: 587 Main St | H22: Cash | I22: Pending | J22: TRK16718651 | K22: 9 | L22: WINTER15 | M22: Instagram | N22: 312.55
A23: ORD200021 | B23: 45613 | C23: C99023 | D23: Monitor | E23: 4 | F23: 342.95 | G23: 569 Main St | H23: Cash | I23: Delivered | J23: TRK52646983 | K23: 6 | M23: Google | N23: 1371.8
A24: ORD200022 | B24: 44955 | C24: C34416 | D24: Monitor | E24: 2 | F24: 49.62 | G24: 633 Main St | H24: Online | I24: Pending | J24: TRK75937350 | K24: 2 | L24: SAVE10 | M24: Google | N24: 99.24
A25: ORD200023 | B25: 45756 | C25: C42372 | D25: Phone | E25: 4 | F25: 273.25 | G25: 755 Main St | H25: Debit Card | I25: Cancelled | J25: TRK36168083 | K25: 5 | L25: FREESHIP | M25: Referral | N25: 1093
A26: ORD200024 | B26: 45595 | C26: C17470 | D26: Laptop | E26: 2 | F26: 230.95 | G26: 956 Main St | H26: Online | I26: Delivered | J26: TRK28775057 | K26: 3 | L26: WINTER15 | M26: Referral | N26: 461.9
A27: ORD200025 | B27: 45497 | C27: C42577 | D27: Monitor | E27: 1 | F27: 399.98 | G27: 709 Main St | H27: Debit Card | I27: Delivered | J27: TRK69423327 | K27: 3 | L27: WINTER15 | M27: Email | N27: 399.98
A28: ORD200026 | B28: 45357 | C28: C21944 | D28: Laptop | E28: 5 | F28: 59.55 | G28: 296 Main St | H28: Online | I28: Delivered | J28: TRK80276812 | K28: 6 | M28: Referral | N28: 297.75
A29: ORD200027 | B29: 45344 | C29: C97593 | D29: Printer | E29: 1 | F29: 472.74 | G29: 881 Main St | H29: Online | I29: Shipped | J29: TRK89117573 | K29: 6 | L29: WINTER15 | M29: Google | N29: 472.74
A30: ORD200028 | B30: 45251 | C30: C59823 | D30: Phone | E30: 4 | F30: 160.07 | G30: 568 Main St | H30: Online | I30: Pending | J30: TRK65895539 | K30: 5 | M30: Email | N30: 640.28
A31: ORD200029 | B31: 45555 | C31: C33260 | D31: Desk | E31: 3 | F31: 423.53 | G31: 930 Main St | H31: Credit Card | I31: Delivered | J31: TRK59744090 | K31: 6 | L31: SAVE10 | M31: Referral | N31: 1270.59
A32: ORD200030 | B32: 45738 | C32: C44267 | D32: Monitor | E32: 2 | F32: 426.7 | G32: 895 Main St | H32: Online | I32: Pending | J32: TRK54751444 | K32: 5 | L32: SAVE10 | M32: Referral | N32: 853.4
A33: ORD200031 | B33: 45107 | C33: C26445 | D33: Chair | E33: 3 | F33: 500.08 | G33: 996 Main St | H33: Debit Card | I33: Returned | J33: TRK31229981 | K33: 6 | M33: Facebook | N33: 1500.24
A34: ORD200032 | B34: 45047 | C34: C12388 | D34: Tablet | E34: 5 | F34: 536.72 | G34: 830 Main St | H34: Cash | I34: Delivered | J34: TRK99261395 | K34: 10 | M34: Email | N34: 2683.6
A35: ORD200033 | B35: 45082 | C35: C52184 | D35: Chair | E35: 1 | F35: 162.77 | G35: 912 Main St | H35: Online | I35: Cancelled | J35: TRK73312471 | K35: 4 | L35: WINTER15 | M35: Facebook | N35: 162.77
A36: ORD200034 | B36: 44933 | C36: C67195 | D36: Chair | E36: 4 | F36: 576.52 | G36: 926 Main St | H36: Credit Card | I36: Pending | J36: TRK55467915 | K36: 5 | L36: WINTER15 | M36: Facebook | N36: 2306.08
A37: ORD200035 | B37: 45633 | C37: C50304 | D37: Monitor | E37: 2 | F37: 465.15 | G37: 128 Main St | H37: Online | I37: Shipped | J37: TRK46850888 | K37: 2 | L37: SAVE10 | M37: Facebook | N37: 930.3
A38: ORD200036 | B38: 45785 | C38: C59337 | D38: Laptop | E38: 2 | F38: 534.43 | G38: 465 Main St | H38: Debit Card | I38: Pending | J38: TRK50961250 | K38: 5 | M38: Facebook | N38: 1068.86
A39: ORD200037 | B39: 45579 | C39: C10054 | D39: Laptop | E39: 2 | F39: 76.74 | G39: 409 Main St | H39: Cash | I39: Returned | J39: TRK94005261 | K39: 7 | L39: SAVE10 | M39: Instagram | N39: 153.48
A40: ORD200038 | B40: 45645 | C40: C15924 | D40: Laptop | E40: 1 | F40: 245.89 | G40: 549 Main St | H40: Debit Card | I40: Delivered | J40: TRK14835975 | K40: 3 | L40: SAVE10 | M40: Google | N40: 245.89
...

Sheet CLEANED DATA
A1: OrderID | B1: Date | C1: Year | D1: Month | E1: CustomerID | F1: Product | G1: Quantity | H1: UnitPrice | I1: ShippingAddress | J1: PaymentMethod | K1: OrderStatus | L1: TrackingNumber | M1: ItemsInCart | N1: CouponCode | O1: ReferralSource | P1: TotalPrice
A2: ORD200000 | B2: 44930 | C2: =TEXT(B2, "yyyy") -> 2023 | D2: =TEXT(B2, "MMM") -> Jan | E2: C72649 | F2: Monitor | G2: 5 | H2: 570.62 | I2: 928 Main St | J2: Debit Card | K2: Shipped | L2: TRK37947903 | M2: 7 | N2: SAVE10 | O2: Instagram | P2: 2853.1
A3: ORD200001 | B3: 45527 | C3: =TEXT(B3, "yyyy") -> 2024 | D3: =TEXT(B3, "MMM") -> Aug | E3: C75739 | F3: Phone | G3: 2 | H3: 151.35 | I3: 823 Main St | J3: Online | K3: Shipped | L3: TRK91186779 | M3: 3 | N3: SAVE10 | O3: Referral | P3: 302.7
A4: ORD200002 | B4: 45349 | C4: =TEXT(B4, "yyyy") -> 2024 | D4: =TEXT(B4, "MMM") -> Feb | E4: C81728 | F4: Tablet | G4: 5 | H4: 550.68 | I4: 512 Main St | J4: Credit Card | K4: Cancelled | L4: TRK42903982 | M4: 8 | N4: FREESHIP | O4: Email | P4: 2753.4
A5: ORD200003 | B5: 45214 | C5: =TEXT(B5, "yyyy") -> 2023 | D5: =TEXT(B5, "MMM") -> Oct | E5: C33540 | F5: Chair | G5: 1 | H5: 273.19 | I5: 275 Main St | J5: Debit Card | K5: Returned | L5: TRK62788070 | M5: 5 | N5: SAVE10 | O5: Facebook | P5: 273.19
A6: ORD200004 | B6: 45785 | C6: =TEXT(B6, "yyyy") -> 2025 | D6: =TEXT(B6, "MMM") -> May | E6: C81840 | F6: Printer | G6: 4 | H6: 626.01 | I6: 668 Main St | J6: Online | K6: Delivered | L6: TRK29241424 | M6: 8 | N6: SAVE10 | O6: Email | P6: 2504.04
A7: ORD200005 | B7: 45222 | C7: =TEXT(B7, "yyyy") -> 2023 | D7: =TEXT(B7, "MMM") -> Oct | E7: C37249 | F7: Phone | G7: 2 | H7: 245.86 | I7: 934 Main St | J7: Credit Card | K7: Shipped | L7: TRK72976927 | M7: 4 | N7: SAVE10 | O7: Instagram | P7: 491.72
A8: ORD200006 | B8: 45825 | C8: =TEXT(B8, "yyyy") -> 2025 | D8: =TEXT(B8, "MMM") -> Jun | E8: C83492 | F8: Laptop | G8: 1 | H8: 664.42 | I8: 986 Main St | J8: Gift Card | K8: Returned | L8: TRK96417362 | M8: 6 | N8: SAVE10 | O8: Facebook | P8: 664.42
A9: ORD200007 | B9: 45058 | C9: =TEXT(B9, "yyyy") -> 2023 | D9: =TEXT(B9, "MMM") -> May | E9: C41460 | F9: Monitor | G9: 5 | H9: 149.55 | I9: 706 Main St | J9: Cash | K9: Shipped | L9: TRK78809193 | M9: 9 | N9: FREESHIP | O9: Facebook | P9: 747.75
A10: ORD200008 | B10: 45749 | C10: =TEXT(B10, "yyyy") -> 2025 | D10: =TEXT(B10, "MMM") -> Apr | E10: C26817 | F10: Phone | G10: 2 | H10: 134.28 | I10: 904 Main St | J10: Gift Card | K10: Cancelled | L10: TRK61042692 | M10: 2 | N10: NO COUPON | O10: Email | P10: 268.56
A11: ORD200009 | B11: 45251 | C11: =TEXT(B11, "yyyy") -> 2023 | D11: =TEXT(B11, "MMM") -> Nov | E11: C31946 | F11: Desk | G11: 4 | H11: 509.38 | I11: 102 Main St | J11: Credit Card | K11: Shipped | L11: TRK33478363 | M11: 6 | N11: SAVE10 | O11: Google | P11: 2037.52
A12: ORD200010 | B12: 45289 | C12: =TEXT(B12, "yyyy") -> 2023 | D12: =TEXT(B12, "MMM") -> Dec | E12: C43443 | F12: Tablet | G12: 5 | H12: 625.97 | I12: 333 Main St | J12: Credit Card | K12: Returned | L12: TRK98859248 | M12: 9 | N12: WINTER15 | O12: Instagram | P12: 3129.85
A13: ORD200011 | B13: 45339 | C13: =TEXT(B13, "yyyy") -> 2024 | D13: =TEXT(B13, "MMM") -> Feb | E13: C93861 | F13: Monitor | G13: 3 | H13: 49.14 | I13: 831 Main St | J13: Online | K13: Returned | L13: TRK48234646 | M13: 7 | N13: SAVE10 | O13: Email | P13: 147.42
... A1201: ORD201199 | B1201: 45088 | C1201: =TEXT(B1201, "yyyy") -> 2023 | D1201: =TEXT(B1201, "MMM") -> Jun | E1201: C57502 | F1201: Tablet | G1201: 4 | H1201: 560.58 | I1201: 201 Main St | J1201: Gift Card | K1201: Returned | L1201: TRK51116746 | M1201: 6 | N1201: SAVE10 | O1201: Referral | P1201: 2242.32

Sheet EDA SUMMARY
D3: EXPLORATORY DATA ANALYSIS
D5: BASIC STATISTICS
B8: TOTAL PRICE: | G8: UNIT PRICE:
B9: Column1 | C9: Column2 | F9: Column1 | G9: Column2
B10: MEAN | C10: =AVERAGE('CLEANED DATA'!$P$2:$P$1201) -> 1053.9683 | F10: MEAN | G10: =AVERAGE('CLEANED DATA'!$H$2:$H$1201) -> 356.41275
B11: MEDIAN | C11: =MEDIAN('CLEANED DATA'!$P$2:$P$1201) -> 823.615 | F11: MEDIAN | G11: =MEDIAN('CLEANED DATA'!$H$2:$H$1201) -> 364.21
B12: COUNT | C12: =COUNTA('CLEANED DATA'!$P$2:$P$1201) -> 1200 | F12: COUNT | G12: =COUNTA('CLEANED DATA'!$H$2:$H$1201) -> 1200
B13: MAX | C13: =MAX('CLEANED DATA'!$P$2:$P$1201) -> 3456.4 | F13: MAX | G13: =MAX('CLEANED DATA'!$H$2:$H$1201) -> 699.93
B14: SUM | C14: =SUM('CLEANED DATA'!$P$2:$P$1201) -> 1264762 | F14: SUM | G14: =SUM('CLEANED DATA'!$H$2:$H$1201) -> 427695.3
B18: QUANTITY: | G18: ITEMS IN CART:
B19: Column1 | C19: Column2 | F19: Column1 | G19: Column2
B20: MEAN | C20: =AVERAGE('CLEANED DATA'!$G$2:$G$1201) -> 2.9458333 | F20: MEAN | G20: =AVERAGE('CLEANED DATA'!$M$2:$M$1201) -> 5.485
B21: MEDIAN | C21: =MEDIAN('CLEANED DATA'!$G$2:$G$1201) -> 3 | F21: MEDIAN | G21: =MEDIAN('CLEANED DATA'!$M$2:$M$1201) -> 5
B22: COUNT | C22: =COUNTA('CLEANED DATA'!$G$2:$G$1201) -> 1200 | F22: COUNT | G22: =COUNTA('CLEANED DATA'!$M$2:$M$1201) -> 1200
B23: MAX | C23: =MAX('CLEANED DATA'!$G$2:$G$1201) -> 5 | F23: MAX | G23: =MAX('CLEANED DATA'!$M$2:$M$1201) -> 10
B24: SUM | C24: =SUM('CLEANED DATA'!$G$2:$G$1201) -> 3535 | F24: SUM | G24: =SUM('CLEANED DATA'!$M$2:$M$1201) -> 6582

Sheet TRENDS
F2: TRENDS
B4: REVENUE BY PRODUCT | E4: ORDERS BY MONTH | H4: REVENUE BY MONTH | L4: ORDER STATUS BREAKDOWN
B5: PRODUCT | C5: REVENUE | E5: MONTH | F5: ORDER COUNT | H5: MONTH | I5: ORDER COUNT | L5: ORDER STATUS | M5: COUNT
B6: Chair | C6: =SUMIF('CLEANED DATA'!$F$2:$F$1201,"Chair",'CLEANED DATA'!$P$2:$P$1201) -> 195620.11 | E6: Jan | F6: =COUNTIF('CLEANED DATA'!$D$2:$D$1201,"Jan") -> 106 | H6: Jan | I6: =SUMIF('CLEANED DATA'!$D$2:$D$1201,"Jan",'CLEANED DATA'!$P$2:$P$1201) -> 124313.23 | L6: Delivered | M6: =COUNTIF('CLEANED DATA'!$K$2:$K$1201,"Delivered") -> 231
B7: Printer | C7: =SUMIF('CLEANED DATA'!$F$2:$F$1201,"Printer",'CLEANED DATA'!$P$2:$P$1201) -> 195612.61 | E7: Feb | F7: =COUNTIF('CLEANED DATA'!$D$2:$D$1201,"Feb") -> 106 | H7: Feb | I7: =SUMIF('CLEANED DATA'!$D$2:$D$1201,"Feb",'CLEANED DATA'!$P$2:$P$1201) -> 112344.78 | L7: Shipped | M7: =COUNTIF('CLEANED DATA'!$K$2:$K$1201,"Shipped") -> 235
B8: Laptop | C8: =SUMIF('CLEANED DATA'!$F$2:$F$1201,"Laptop",'CLEANED DATA'!$P$2:$P$1201) -> 192126.56 | E8: Mar | F8: =COUNTIF('CLEANED DATA'!$D$2:$D$1201,"Mar") -> 128 | H8: Mar | I8: =SUMIF('CLEANED DATA'!$D$2:$D$1201,"Mar",'CLEANED DATA'!$P$2:$P$1201) -> 123840.93 | L8: Pending | M8: =COUNTIF('CLEANED DATA'!$K$2:$K$1201,"Pending") -> 237
B9: Tablet | C9: =SUMIF('CLEANED DATA'!$F$2:$F$1201,"Tablet",'CLEANED DATA'!$P$2:$P$1201) -> 186568.95 | E9: Apr | F9: =COUNTIF('CLEANED DATA'!$D$2:$D$1201,"Apr") -> 113 | H9: Apr | I9: =SUMIF('CLEANED DATA'!$D$2:$D$1201,"Apr",'CLEANED DATA'!$P$2:$P$1201) -> 109186.05 | L9: Cancelled | M9: =COUNTIF('CLEANED DATA'!$K$2:$K$1201,"Cancelled") -> 250
B10: Monitor | C10: =SUMIF('CLEANED DATA'!$F$2:$F$1201,"Monitor",'CLEANED DATA'!$P$2:$P$1201) -> 175651.41 | E10: May | F10: =COUNTIF('CLEANED DATA'!$D$2:$D$1201,"May") -> 120 | H10: May | I10: =SUMIF('CLEANED DATA'!$D$2:$D$1201,"May",'CLEANED DATA'!$P$2:$P$1201) -> 135142.59 | L10: Returned | M10: =COUNTIF('CLEANED DATA'!$K$2:$K$1201,"Returned") -> 247
B11: Desk | C11: =SUMIF('CLEANED DATA'!$F$2:$F$1201,"Desk",'CLEANED DATA'!$P$2:$P$1201) -> 167459.93 | E11: Jun | F11: =COUNTIF('CLEANED DATA'!$D$2:$D$1201,"Jun") -> 147 | H11: Jun | I11: =SUMIF('CLEANED DATA'!$D$2:$D$1201,"Jun",'CLEANED DATA'!$P$2:$P$1201) -> 170616.13 | L11: GRAND TOTAL | M11: =SUM(M6:M10) -> 1200
B12: Phone | C12: =SUMIF('CLEANED DATA'!$F$2:$F$1201,"Phone",'CLEANED DATA'!$P$2:$P$1201) -> 151722.39 | E12: Jul | F12: =COUNTIF('CLEANED DATA'!$D$2:$D$1201,"Jul") -> 87 | H12: Jul | I12: =SUMIF('CLEANED DATA'!$D$2:$D$1201,"Jul",'CLEANED DATA'!$P$2:$P$1201) -> 85784.64
B13: GRAND TOTAL | C13: =SUM(C6:C12) -> 1264762 | E13: Aug | F13: =COUNTIF('CLEANED DATA'!$D$2:$D$1201,"Aug") -> 79 | H13: Aug | I13: =SUMIF('CLEANED DATA'!$D$2:$D$1201,"Aug",'CLEANED DATA'!$P$2:$P$1201) -> 86343.21 | L13: REVENUE BY REFERRAL SOURCE
E14: Sept | F14: =COUNTIF('CLEANED DATA'!$D$2:$D$1201,"Sept") -> 73 | H14: Sept | I14: =SUMIF('CLEANED DATA'!$D$2:$D$1201,"Sept",'CLEANED DATA'!$P$2:$P$1201) -> 69321.65 | L14: REFERRAL SOURCE | M14: REVENUE
E15: Oct | F15: =COUNTIF('CLEANED DATA'!$D$2:$D$1201,"Oct") -> 78 | H15: Oct | I15: =SUMIF('CLEANED DATA'!$D$2:$D$1201,"Oct",'CLEANED DATA'!$P$2:$P$1201) -> 89834.82 | L15: Instagram | M15: =SUMIF('CLEANED DATA'!$O$2:$O$1201,"Instagram",'CLEANED DATA'!$P$2:$P$1201) -> 275285.45
E16: Nov | F16: =COUNTIF('CLEANED DATA'!$D$2:$D$1201,"Nov") -> 76 | H16: Nov | I16: =SUMIF('CLEANED DATA'!$D$2:$D$1201,"Nov",'CLEANED DATA'!$P$2:$P$1201) -> 75493.43 | L16: Email | M16: =SUMIF('CLEANED DATA'!$O$2:$O$1201,"Email",'CLEANED DATA'!$P$2:$P$1201) -> 261808.55
B17: REVENUE BY YEAR | E17: Dec | F17: =COUNTIF('CLEANED DATA'!$D$2:$D$1201,"Dec") -> 87 | H17: Dec | I17: =SUMIF('CLEANED DATA'!$D$2:$D$1201,"Dec",'CLEANED DATA'!$P$2:$P$1201) -> 82540.5 | L17: Google | M17: =SUMIF('CLEANED DATA'!$O$2:$O$1201,"Google",'CLEANED DATA'!$P$2:$P$1201) -> 250441.48
B18: YEAR | C18: REVENUE | E18: TOTAL | F18: =SUM(F6:F17) -> 1200 | H18: GRAND TOTAL | I18: =SUM(I6:I17) -> 1264762 | L18: Facebook | M18: =SUMIF('CLEANED DATA'!$O$2:$O$1201,"Facebook",'CLEANED DATA'!$P$2:$P$1201) -> 250410.9
B19: 2023 | C19: =SUMIF('CLEANED DATA'!$C$2:$C$1201,2023,'CLEANED DATA'!$P$2:$P$1201) -> 552643.24 | L19: Referral | M19: =SUMIF('CLEANED DATA'!$O$2:$O$1201,"Referral",'CLEANED DATA'!$P$2:$P$1201) -> 226815.58
B20: 2024 | C20: =SUMIF('CLEANED DATA'!$C$2:$C$1201,2024,'CLEANED DATA'!$P$2:$P$1201) -> 480235.87 | L20: GRAND TOTAL | M20: =SUM(M15:M19) -> 1264762
B21: 2025 | C21: =SUMIF('CLEANED DATA'!$C$2:$C$1201,2025,'CLEANED DATA'!$P$2:$P$1201) -> 231882.85
B22: GRAND TOTAL | C22: =-SUM(C19:C21) -> -1264762

Sheet OUTLIERS
C2: OUTLIERS | H2: PRODUCTS WITH OUTLIER ORDERS
B4: Column1 | C4: Column2 | D4: Column3 | H4: Product | I4: Number
B5: Q1 (Quartile) | D5: =QUARTILE('CLEANED DATA'!$P$2:$P$1201,1) -> 410.52 | H5: Laptop | I5: =COUNTIFS('CLEANED DATA'!$F$2:$F$1201,"Laptop",'CLEANED DATA'!$P$2:$P$1201,">"&D9) -> 2
B6: Q3 (Quartile) | D6: =QUARTILE('CLEANED DATA'!$P$2:$P$1201,3) -> 1578.475 | H6: Monitor | I6: =COUNTIFS('CLEANED DATA'!$F$2:$F$1201,"Monitor",'CLEANED DATA'!$P$2:$P$1201,">"&D9) -> 1
B7: IQR (Interquartile Range) | D7: =D6-D5 -> 1167.955 | H7: Phone | I7: =COUNTIFS('CLEANED DATA'!$F$2:$F$1201,"Phone",'CLEANED DATA'!$P$2:$P$1201,">"&D9) -> 0
B8: Lower Bound | D8: =D5-(1.5*D7) -> -1341.4125 | H8: Tablet | I8: =COUNTIFS('CLEANED DATA'!$F$2:$F$1201,"Tablet",'CLEANED DATA'!$P$2:$P$1201,">"&D9) -> 2
B9: Upper Bound | D9: =D6+(1.5*D7) -> 3330.4075 | H9: Chair | I9: =COUNTIFS('CLEANED DATA'!$F$2:$F$1201,"Chair",'CLEANED DATA'!$P$2:$P$1201,">"&D9) -> 1
B10: Outlier Count | D10: =COUNTIF('CLEANED DATA'!$P$2:$P$1201,"<"&D8)+COUNTIF('CLEANED DATA'!$P$2:$P$1201,">"&D9) -> 8 | H10: Desk | I10: =COUNTIFS('CLEANED DATA'!$F$2:$F$1201,"Desk",'CLEANED DATA'!$P$2:$P$1201,">"&D9) -> 0
H11: Printer | I11: =COUNTIFS('CLEANED DATA'!$F$2:$F$1201,"Printer",'CLEANED DATA'!$P$2:$P$1201,">"&D9) -> 2

Sheet KEY OBSERVATIONS
I2: KEY OBSERVATIONS
J4: PARAMETER | K4: OBSERVATION
J5: Monthly Sales | K5: June was the peak month for orders (147 orders) with a noticeable dip in September (73 orders) — nearly half the volume.
J6: Yearly Revenue | K6: 2023 was the highest revenue year ($552,643), with 2024 slightly lower at $480,236. 2025 is still ongoing.
J7: Revenue by product | K7: Chair and Printer led in total revenue (Approx. $195K each), while Phone was the lowest earner at ~$151K. However, Laptop had the highest average order value at ~$1,110.
J8: Most profitable Referral source | K8: Instagram was the top referral source, generating the most revenue at ~$275K — making it the most valuable customer acquisition channel.
J9: Order status Report | K9: 41.4% of orders were either Cancelled or Returned (497 out of 1,200). This is the most critical finding — nearly half of all orders never completed successfully.
J10: Outlier report | K10: 8 outlier orders were identified in TotalPrice using the IQR method, spread across Laptop, Monitor, Tablet, Chair and Printer — all high-quantity purchases at premium unit prices.
